Enter passphrase for /home/caplierr/.ssh/github: Enter passphrase for /home/caplierr/.ssh/github: Traceback (most recent call last):
  File "/home/caplierr/code/CGvsNI-SSL/src/ssl/utils/tools.py", line 48, in get_latest_log
    latest_log = list_logs[0]
IndexError: list index out of range

During handling of the above exception, another exception occurred:

Traceback (most recent call last):
  File "./test_cgvsni.py", line 118, in <module>
    main()
  File "./test_cgvsni.py", line 107, in main
    method.train(dataset_train, model, optimizer, 0, args.epochs, model_path, args.verbose)
  File "/home/caplierr/code/CGvsNI-SSL/src/ssl/methods/base.py", line 317, in train
    self._update_checkpoint(model, epoch)
  File "/home/caplierr/code/CGvsNI-SSL/src/ssl/methods/base.py", line 88, in _update_checkpoint
    latest_log, _ = get_latest_log(self.main_path)
  File "/home/caplierr/code/CGvsNI-SSL/src/ssl/utils/tools.py", line 50, in get_latest_log
    raise RuntimeError('No logs were found')
RuntimeError: No logs were found
Enter passphrase for /home/caplierr/.ssh/github: Enter passphrase for /home/caplierr/.ssh/github: 